Workbook

Sheet Previsioni partecipanti
A1: # | B1: Data | C1: Orario (IT) | D1: Girone | E1: Squadra Casa | F1: Squadra Ospite | G1: Esito | H1: Leo Proietti | I1: =SUM(I3:I74) -> 0 | J1: Jack | K1: =SUM(K3:K74) -> 0 | L1: Antonella | M1: =SUM(M3:M74) -> 0 | N1: Vito | O1: =SUM(O3:O74) -> 0 | P1: Samuele | Q1: =SUM(Q3:Q74) -> 0 | R1: Valerio | S1: =SUM(S3:S74) -> 0 | T1: Edoardo | U1: =SUM(U3:U74) -> 0 | V1: Tania | W1: =SUM(W3:W74) -> 0 | X1: Pier | Y1: =SUM(Y3:Y74) -> 0 | Z1: Alessandra C. | AA1: =SUM(AA3:AA74) -> 0 | AB1: Alessandra P. | AC1: =SUM(AC3:AC74) -> 0 | AD1: Claudia A. | AE1: =SUM(AE3:AE74) -> 0 | AF1: Marco G. | AG1: =SUM(AG3:AG74) -> 0 | AH1: Alessio S. | AI1: =SUM(AI3:AI74) -> 0 | AJ1: Alessio R. | AK1: =SUM(AK3:AK74) -> 0 | AL1: Marco P. | AM1: =SUM(AM3:AM74) -> 0 | AN1: Khawla | AO1: =SUM(AO3:AO74) -> 0 | AP1: Federico R. | AQ1: =SUM(AQ3:AQ74) -> 0
G2: ESITO | H2: Esito previsto | I2: Punti | J2: Esito previsto | K2: Punti | L2: Esito previsto | M2: Punti | N2: Esito previsto | O2: Punti | P2: Esito previsto | Q2: Punti | R2: Esito previsto | S2: Punti | T2: Esito previsto | U2: Punti | V2: Esito previsto | W2: Punti | X2: Esito previsto | Y2: Punti | Z2: Esito previsto | AA2: Punti | AB2: Esito previsto | AC2: Punti | AD2: Esito previsto | AE2: Punti | AF2: Esito previsto | AG2: Punti | AH2: Esito previsto | AI2: Punti | AJ2: Esito previsto | AK2: Punti | AL2: Esito previsto | AM2: Punti | AN2: Esito previsto | AO2: Punti | AP2: Esito previsto | AQ2: Punti
A3: 1 | B3: Gio 11 giu | C3: 21:00 | D3: Girone A | E3: Messico | F3: Sudafrica | H3: 1 | I3: =IF($G3<>"",IF(H3=$G3,1,0),"") | J3: 1 | K3: =IF($G3<>"",IF(J3=$G3,1,0),"") | L3: 1 | M3: =IF($G3<>"",IF(L3=$G3,1,0),"") | N3: X | O3: =IF($G3<>"",IF(N3=$G3,1,0),"") | P3: 1 | Q3: =IF($G3<>"",IF(P3=$G3,1,0),"") | R3: 1 | S3: =IF($G3<>"",IF(R3=$G3,1,0),"") | T3: 1 | U3: =IF($G3<>"",IF(T3=$G3,1,0),"") | V3: 1 | W3: =IF($G3<>"",IF(V3=$G3,1,0),"") | X3: 1 | Y3: =IF($G3<>"",IF(X3=$G3,1,0),"") | Z3: X | AA3: =IF($G3<>"",IF(Z3=$G3,1,0),"") | AB3: X | AC3: =IF($G3<>"",IF(AB3=$G3,1,0),"") | AD3: 1 | AE3: =IF($G3<>"",IF(AD3=$G3,1,0),"") | AF3: 2 | AG3: =IF($G3<>"",IF(AF3=$G3,1,0),"") | AH3: 1 | AI3: =IF($G3<>"",IF(AH3=$G3,1,0),"") | AJ3: 1 | AK3: =IF($G3<>"",IF(AJ3=$G3,1,0),"") | AL3: 1 | AM3: =IF($G3<>"",IF(AL3=$G3,1,0),"") | AN3: 1 | AO3: =IF($G3<>"",IF(AN3=$G3,1,0),"") | AP3: 1 | AQ3: =IF($G3<>"",IF(AP3=$G3,1,0),"")
A4: 2 | B4: Ven 12 giu | C4: 04:00 | D4: Girone A | E4: Corea del Sud | F4: Repubblica Ceca | H4: 1 | I4: =IF($G4<>"",IF(H4=$G4,1,0),"") | J4: 2 | K4: =IF($G4<>"",IF(J4=$G4,1,0),"") | L4: 2 | M4: =IF($G4<>"",IF(L4=$G4,1,0),"") | N4: 2 | O4: =IF($G4<>"",IF(N4=$G4,1,0),"") | P4: X | Q4: =IF($G4<>"",IF(P4=$G4,1,0),"") | R4: X | S4: =IF($G4<>"",IF(R4=$G4,1,0),"") | T4: X | U4: =IF($G4<>"",IF(T4=$G4,1,0),"") | V4: X | W4: =IF($G4<>"",IF(V4=$G4,1,0),"") | X4: 1 | Y4: =IF($G4<>"",IF(X4=$G4,1,0),"") | Z4: 2 | AA4: =IF($G4<>"",IF(Z4=$G4,1,0),"") | AB4: 1 | AC4: =IF($G4<>"",IF(AB4=$G4,1,0),"") | AD4: 2 | AE4: =IF($G4<>"",IF(AD4=$G4,1,0),"") | AF4: 1 | AG4: =IF($G4<>"",IF(AF4=$G4,1,0),"") | AH4: X | AI4: =IF($G4<>"",IF(AH4=$G4,1,0),"") | AJ4: 1 | AK4: =IF($G4<>"",IF(AJ4=$G4,1,0),"") | AL4: 1 | AM4: =IF($G4<>"",IF(AL4=$G4,1,0),"") | AN4: 1 | AO4: =IF($G4<>"",IF(AN4=$G4,1,0),"") | AP4: 1 | AQ4: =IF($G4<>"",IF(AP4=$G4,1,0),"")
A5: 3 | B5: Ven 12 giu | C5: 21:00 | D5: Girone B | E5: Canada | F5: Bosnia-Erzegovina | H5: X | I5: =IF($G5<>"",IF(H5=$G5,1,0),"") | J5: X | K5: =IF($G5<>"",IF(J5=$G5,1,0),"") | L5: X | M5: =IF($G5<>"",IF(L5=$G5,1,0),"") | N5: 2 | O5: =IF($G5<>"",IF(N5=$G5,1,0),"") | P5: 1 | Q5: =IF($G5<>"",IF(P5=$G5,1,0),"") | R5: 2 | S5: =IF($G5<>"",IF(R5=$G5,1,0),"") | T5: 1 | U5: =IF($G5<>"",IF(T5=$G5,1,0),"") | V5: 1 | W5: =IF($G5<>"",IF(V5=$G5,1,0),"") | X5: 1 | Y5: =IF($G5<>"",IF(X5=$G5,1,0),"") | Z5: 1 | AA5: =IF($G5<>"",IF(Z5=$G5,1,0),"") | AB5: 1 | AC5: =IF($G5<>"",IF(AB5=$G5,1,0),"") | AD5: 1 | AE5: =IF($G5<>"",IF(AD5=$G5,1,0),"") | AF5: 2 | AG5: =IF($G5<>"",IF(AF5=$G5,1,0),"") | AH5: 1 | AI5: =IF($G5<>"",IF(AH5=$G5,1,0),"") | AJ5: 1 | AK5: =IF($G5<>"",IF(AJ5=$G5,1,0),"") | AL5: 2 | AM5: =IF($G5<>"",IF(AL5=$G5,1,0),"") | AN5: 1 | AO5: =IF($G5<>"",IF(AN5=$G5,1,0),"") | AP5: 1 | AQ5: =IF($G5<>"",IF(AP5=$G5,1,0),"")
A6: 4 | B6: Sab 13 giu | C6: 03:00 | D6: Girone D | E6: Stati Uniti | F6: Paraguay | H6: X | I6: =IF($G6<>"",IF(H6=$G6,1,0),"") | J6: 1 | K6: =IF($G6<>"",IF(J6=$G6,1,0),"") | L6: 1 | M6: =IF($G6<>"",IF(L6=$G6,1,0),"") | N6: 1 | O6: =IF($G6<>"",IF(N6=$G6,1,0),"") | P6: X | Q6: =IF($G6<>"",IF(P6=$G6,1,0),"") | R6: 1 | S6: =IF($G6<>"",IF(R6=$G6,1,0),"") | T6: X | U6: =IF($G6<>"",IF(T6=$G6,1,0),"") | V6: 1 | W6: =IF($G6<>"",IF(V6=$G6,1,0),"") | X6: 1 | Y6: =IF($G6<>"",IF(X6=$G6,1,0),"") | Z6: X | AA6: =IF($G6<>"",IF(Z6=$G6,1,0),"") | AB6: X | AC6: =IF($G6<>"",IF(AB6=$G6,1,0),"") | AD6: 1 | AE6: =IF($G6<>"",IF(AD6=$G6,1,0),"") | AF6: x | AG6: =IF($G6<>"",IF(AF6=$G6,1,0),"") | AH6: 1 | AI6: =IF($G6<>"",IF(AH6=$G6,1,0),"") | AJ6: 1 | AK6: =IF($G6<>"",IF(AJ6=$G6,1,0),"") | AL6: X | AM6: =IF($G6<>"",IF(AL6=$G6,1,0),"") | AN6: 1 | AO6: =IF($G6<>"",IF(AN6=$G6,1,0),"") | AP6: 1 | AQ6: =IF($G6<>"",IF(AP6=$G6,1,0),"")
A7: 5 | B7: Sab 13 giu | C7: 21:00 | D7: Girone B | E7: Qatar | F7: Svizzera | H7: 2 | I7: =IF($G7<>"",IF(H7=$G7,1,0),"") | J7: 2 | K7: =IF($G7<>"",IF(J7=$G7,1,0),"") | L7: 1 | M7: =IF($G7<>"",IF(L7=$G7,1,0),"") | N7: 2 | O7: =IF($G7<>"",IF(N7=$G7,1,0),"") | P7: 2 | Q7: =IF($G7<>"",IF(P7=$G7,1,0),"") | R7: 2 | S7: =IF($G7<>"",IF(R7=$G7,1,0),"") | T7: 2 | U7: =IF($G7<>"",IF(T7=$G7,1,0),"") | V7: 2 | W7: =IF($G7<>"",IF(V7=$G7,1,0),"") | X7: 2 | Y7: =IF($G7<>"",IF(X7=$G7,1,0),"") | Z7: 1 | AA7: =IF($G7<>"",IF(Z7=$G7,1,0),"") | AB7: 2 | AC7: =IF($G7<>"",IF(AB7=$G7,1,0),"") | AD7: X | AE7: =IF($G7<>"",IF(AD7=$G7,1,0),"") | AF7: 2 | AG7: =IF($G7<>"",IF(AF7=$G7,1,0),"") | AH7: 2 | AI7: =IF($G7<>"",IF(AH7=$G7,1,0),"") | AJ7: 2 | AK7: =IF($G7<>"",IF(AJ7=$G7,1,0),"") | AL7: 2 | AM7: =IF($G7<>"",IF(AL7=$G7,1,0),"") | AN7: 2 | AO7: =IF($G7<>"",IF(AN7=$G7,1,0),"") | AP7: 2 | AQ7: =IF($G7<>"",IF(AP7=$G7,1,0),"")
A8: 6 | B8: Dom 14 giu | C8: 24:00 | D8: Girone C | E8: Brasile | F8: Marocco | H8: 1 | I8: =IF($G8<>"",IF(H8=$G8,1,0),"") | J8: 1 | K8: =IF($G8<>"",IF(J8=$G8,1,0),"") | L8: 1 | M8: =IF($G8<>"",IF(L8=$G8,1,0),"") | N8: X | O8: =IF($G8<>"",IF(N8=$G8,1,0),"") | P8: X | Q8: =IF($G8<>"",IF(P8=$G8,1,0),"") | R8: X | S8: =IF($G8<>"",IF(R8=$G8,1,0),"") | T8: 1 | U8: =IF($G8<>"",IF(T8=$G8,1,0),"") | V8: X | W8: =IF($G8<>"",IF(V8=$G8,1,0),"") | X8: X | Y8: =IF($G8<>"",IF(X8=$G8,1,0),"") | Z8: 1 | AA8: =IF($G8<>"",IF(Z8=$G8,1,0),"") | AB8: X | AC8: =IF($G8<>"",IF(AB8=$G8,1,0),"") | AD8: 1 | AE8: =IF($G8<>"",IF(AD8=$G8,1,0),"") | AF8: 1 | AG8: =IF($G8<>"",IF(AF8=$G8,1,0),"") | AH8: 1 | AI8: =IF($G8<>"",IF(AH8=$G8,1,0),"") | AJ8: X | AK8: =IF($G8<>"",IF(AJ8=$G8,1,0),"") | AL8: X | AM8: =IF($G8<>"",IF(AL8=$G8,1,0),"") | AN8: 1 | AO8: =IF($G8<>"",IF(AN8=$G8,1,0),"") | AP8: 1 | AQ8: =IF($G8<>"",IF(AP8=$G8,1,0),"")
A9: 7 | B9: Dom 14 giu | C9: 03:00 | D9: Girone C | E9: Haiti | F9: Scozia | H9: 2 | I9: =IF($G9<>"",IF(H9=$G9,1,0),"") | J9: 2 | K9: =IF($G9<>"",IF(J9=$G9,1,0),"") | L9: 2 | M9: =IF($G9<>"",IF(L9=$G9,1,0),"") | N9: 2 | O9: =IF($G9<>"",IF(N9=$G9,1,0),"") | P9: 2 | Q9: =IF($G9<>"",IF(P9=$G9,1,0),"") | R9: 2 | S9: =IF($G9<>"",IF(R9=$G9,1,0),"") | T9: 2 | U9: =IF($G9<>"",IF(T9=$G9,1,0),"") | V9: X | W9: =IF($G9<>"",IF(V9=$G9,1,0),"") | X9: 2 | Y9: =IF($G9<>"",IF(X9=$G9,1,0),"") | Z9: X | AA9: =IF($G9<>"",IF(Z9=$G9,1,0),"") | AB9: 2 | AC9: =IF($G9<>"",IF(AB9=$G9,1,0),"") | AD9: 2 | AE9: =IF($G9<>"",IF(AD9=$G9,1,0),"") | AF9: 2 | AG9: =IF($G9<>"",IF(AF9=$G9,1,0),"") | AH9: 2 | AI9: =IF($G9<>"",IF(AH9=$G9,1,0),"") | AJ9: X | AK9: =IF($G9<>"",IF(AJ9=$G9,1,0),"") | AL9: X | AM9: =IF($G9<>"",IF(AL9=$G9,1,0),"") | AN9: 2 | AO9: =IF($G9<>"",IF(AN9=$G9,1,0),"") | AP9: 2 | AQ9: =IF($G9<>"",IF(AP9=$G9,1,0),"")
A10: 8 | B10: Dom 14 giu | C10: 06:00 | D10: Girone D | E10: Australia | F10: Turchia | H10: 2 | I10: =IF($G10<>"",IF(H10=$G10,1,0),"") | J10: 2 | K10: =IF($G10<>"",IF(J10=$G10,1,0),"") | L10: X | M10: =IF($G10<>"",IF(L10=$G10,1,0),"") | N10: 2 | O10: =IF($G10<>"",IF(N10=$G10,1,0),"") | P10: 2 | Q10: =IF($G10<>"",IF(P10=$G10,1,0),"") | R10: 2 | S10: =IF($G10<>"",IF(R10=$G10,1,0),"") | T10: 2 | U10: =IF($G10<>"",IF(T10=$G10,1,0),"") | V10: 2 | W10: =IF($G10<>"",IF(V10=$G10,1,0),"") | X10: 2 | Y10: =IF($G10<>"",IF(X10=$G10,1,0),"") | Z10: 2 | AA10: =IF($G10<>"",IF(Z10=$G10,1,0),"") | AB10: 2 | AC10: =IF($G10<>"",IF(AB10=$G10,1,0),"") | AD10: X | AE10: =IF($G10<>"",IF(AD10=$G10,1,0),"") | AF10: x | AG10: =IF($G10<>"",IF(AF10=$G10,1,0),"") | AH10: 2 | AI10: =IF($G10<>"",IF(AH10=$G10,1,0),"") | AJ10: 1 | AK10: =IF($G10<>"",IF(AJ10=$G10,1,0),"") | AL10: 1 | AM10: =IF($G10<>"",IF(AL10=$G10,1,0),"") | AN10: 2 | AO10: =IF($G10<>"",IF(AN10=$G10,1,0),"") | AP10: 2 | AQ10: =IF($G10<>"",IF(AP10=$G10,1,0),"")
A11: 9 | B11: Dom 14 giu | C11: 19:00 | D11: Girone E | E11: Germania | F11: Curaçao | H11: 1 | I11: =IF($G11<>"",IF(H11=$G11,1,0),"") | J11: 1 | K11: =IF($G11<>"",IF(J11=$G11,1,0),"") | L11: 1 | M11: =IF($G11<>"",IF(L11=$G11,1,0),"") | N11: 1 | O11: =IF($G11<>"",IF(N11=$G11,1,0),"") | P11: 1 | Q11: =IF($G11<>"",IF(P11=$G11,1,0),"") | R11: 1 | S11: =IF($G11<>"",IF(R11=$G11,1,0),"") | T11: 1 | U11: =IF($G11<>"",IF(T11=$G11,1,0),"") | V11: 1 | W11: =IF($G11<>"",IF(V11=$G11,1,0),"") | X11: 1 | Y11: =IF($G11<>"",IF(X11=$G11,1,0),"") | Z11: 1 | AA11: =IF($G11<>"",IF(Z11=$G11,1,0),"") | AB11: 1 | AC11: =IF($G11<>"",IF(AB11=$G11,1,0),"") | AD11: 1 | AE11: =IF($G11<>"",IF(AD11=$G11,1,0),"") | AF11: 1 | AG11: =IF($G11<>"",IF(AF11=$G11,1,0),"") | AH11: 1 | AI11: =IF($G11<>"",IF(AH11=$G11,1,0),"") | AJ11: 1 | AK11: =IF($G11<>"",IF(AJ11=$G11,1,0),"") | AL11: 1 | AM11: =IF($G11<>"",IF(AL11=$G11,1,0),"") | AN11: 1 | AO11: =IF($G11<>"",IF(AN11=$G11,1,0),"") | AP11: 1 | AQ11: =IF($G11<>"",IF(AP11=$G11,1,0),"")
A12: 10 | B12: Dom 14 giu | C12: 22:00 | D12: Girone F | E12: Paesi Bassi | F12: Giappone | H12: 1 | I12: =IF($G12<>"",IF(H12=$G12,1,0),"") | J12: 1 | K12: =IF($G12<>"",IF(J12=$G12,1,0),"") | L12: 1 | M12: =IF($G12<>"",IF(L12=$G12,1,0),"") | N12: 2 | O12: =IF($G12<>"",IF(N12=$G12,1,0),"") | P12: X | Q12: =IF($G12<>"",IF(P12=$G12,1,0),"") | R12: 1 | S12: =IF($G12<>"",IF(R12=$G12,1,0),"") | T12: 1 | U12: =IF($G12<>"",IF(T12=$G12,1,0),"") | V12: 1 | W12: =IF($G12<>"",IF(V12=$G12,1,0),"") | X12: 1 | Y12: =IF($G12<>"",IF(X12=$G12,1,0),"") | Z12: 1 | AA12: =IF($G12<>"",IF(Z12=$G12,1,0),"") | AB12: 2 | AC12: =IF($G12<>"",IF(AB12=$G12,1,0),"") | AD12: 1 | AE12: =IF($G12<>"",IF(AD12=$G12,1,0),"") | AF12: 1 | AG12: =IF($G12<>"",IF(AF12=$G12,1,0),"") | AH12: 1 | AI12: =IF($G12<>"",IF(AH12=$G12,1,0),"") | AJ12: 1 | AK12: =IF($G12<>"",IF(AJ12=$G12,1,0),"") | AL12: 1 | AM12: =IF($G12<>"",IF(AL12=$G12,1,0),"") | AN12: 1 | AO12: =IF($G12<>"",IF(AN12=$G12,1,0),"") | AP12: 1 | AQ12: =IF($G12<>"",IF(AP12=$G12,1,0),"")
A13: 11 | B13: Lun 15 giu | C13: 01:00 | D13: Girone E | E13: Costa d'Avorio | F13: Ecuador | H13: 1 | I13: =IF($G13<>"",IF(H13=$G13,1,0),"") | J13: X | K13: =IF($G13<>"",IF(J13=$G13,1,0),"") | L13: X | M13: =IF($G13<>"",IF(L13=$G13,1,0),"") | N13: 1 | O13: =IF($G13<>"",IF(N13=$G13,1,0),"") | P13: X | Q13: =IF($G13<>"",IF(P13=$G13,1,0),"") | R13: X | S13: =IF($G13<>"",IF(R13=$G13,1,0),"") | T13: 2 | U13: =IF($G13<>"",IF(T13=$G13,1,0),"") | V13: 1 | W13: =IF($G13<>"",IF(V13=$G13,1,0),"") | X13: 2 | Y13: =IF($G13<>"",IF(X13=$G13,1,0),"") | Z13: X | AA13: =IF($G13<>"",IF(Z13=$G13,1,0),"") | AB13: 1 | AC13: =IF($G13<>"",IF(AB13=$G13,1,0),"") | AD13: X | AE13: =IF($G13<>"",IF(AD13=$G13,1,0),"") | AF13: 1 | AG13: =IF($G13<>"",IF(AF13=$G13,1,0),"") | AH13: X | AI13: =IF($G13<>"",IF(AH13=$G13,1,0),"") | AJ13: 1 | AK13: =IF($G13<>"",IF(AJ13=$G13,1,0),"") | AL13: 2 | AM13: =IF($G13<>"",IF(AL13=$G13,1,0),"") | AN13: 1 | AO13: =IF($G13<>"",IF(AN13=$G13,1,0),"") | AP13: 2 | AQ13: =IF($G13<>"",IF(AP13=$G13,1,0),"")
A14: 12 | B14: Lun 15 giu | C14: 04:00 | D14: Girone F | E14: Svezia | F14: Tunisia | H14: X | I14: =IF($G14<>"",IF(H14=$G14,1,0),"") | J14: 1 | K14: =IF($G14<>"",IF(J14=$G14,1,0),"") | L14: X | M14: =IF($G14<>"",IF(L14=$G14,1,0),"") | N14: X | O14: =IF($G14<>"",IF(N14=$G14,1,0),"") | P14: 1 | Q14: =IF($G14<>"",IF(P14=$G14,1,0),"") | R14: 1 | S14: =IF($G14<>"",IF(R14=$G14,1,0),"") | T14: 1 | U14: =IF($G14<>"",IF(T14=$G14,1,0),"") | V14: 1 | W14: =IF($G14<>"",IF(V14=$G14,1,0),"") | X14: 1 | Y14: =IF($G14<>"",IF(X14=$G14,1,0),"") | Z14: 1 | AA14: =IF($G14<>"",IF(Z14=$G14,1,0),"") | AB14: 1 | AC14: =IF($G14<>"",IF(AB14=$G14,1,0),"") | AD14: X | AE14: =IF($G14<>"",IF(AD14=$G14,1,0),"") | AF14: 1 | AG14: =IF($G14<>"",IF(AF14=$G14,1,0),"") | AH14: 1 | AI14: =IF($G14<>"",IF(AH14=$G14,1,0),"") | AJ14: 2 | AK14: =IF($G14<>"",IF(AJ14=$G14,1,0),"") | AL14: 1 | AM14: =IF($G14<>"",IF(AL14=$G14,1,0),"") | AN14: 1 | AO14: =IF($G14<>"",IF(AN14=$G14,1,0),"") | AP14: 2 | AQ14: =IF($G14<>"",IF(AP14=$G14,1,0),"")
A15: 13 | B15: Lun 15 giu | C15: 18:00 | D15: Girone H | E15: Spagna | F15: Capo Verde | H15: 1 | I15: =IF($G15<>"",IF(H15=$G15,1,0),"") | J15: 1 | K15: =IF($G15<>"",IF(J15=$G15,1,0),"") | L15: 1 | M15: =IF($G15<>"",IF(L15=$G15,1,0),"") | N15: 1 | O15: =IF($G15<>"",IF(N15=$G15,1,0),"") | P15: 1 | Q15: =IF($G15<>"",IF(P15=$G15,1,0),"") | R15: 1 | S15: =IF($G15<>"",IF(R15=$G15,1,0),"") | T15: 1 | U15: =IF($G15<>"",IF(T15=$G15,1,0),"") | V15: 1 | W15: =IF($G15<>"",IF(V15=$G15,1,0),"") | X15: 1 | Y15: =IF($G15<>"",IF(X15=$G15,1,0),"") | Z15: 1 | AA15: =IF($G15<>"",IF(Z15=$G15,1,0),"") | AB15: 1 | AC15: =IF($G15<>"",IF(AB15=$G15,1,0),"") | AD15: 1 | AE15: =IF($G15<>"",IF(AD15=$G15,1,0),"") | AF15: 1 | AG15: =IF($G15<>"",IF(AF15=$G15,1,0),"") | AH15: 1 | AI15: =IF($G15<>"",IF(AH15=$G15,1,0),"") | AJ15: 1 | AK15: =IF($G15<>"",IF(AJ15=$G15,1,0),"") | AL15: 1 | AM15: =IF($G15<>"",IF(AL15=$G15,1,0),"") | AN15: 1 | AO15: =IF($G15<>"",IF(AN15=$G15,1,0),"") | AP15: 1 | AQ15: =IF($G15<>"",IF(AP15=$G15,1,0),"")
A16: 14 | B16: Lun 15 giu | C16: 21:00 | D16: Girone G | E16: Belgio | F16: Egitto | H16: 1 | I16: =IF($G16<>"",IF(H16=$G16,1,0),"") | J16: 1 | K16: =IF($G16<>"",IF(J16=$G16,1,0),"") | L16: X | M16: =IF($G16<>"",IF(L16=$G16,1,0),"") | N16: 2 | O16: =IF($G16<>"",IF(N16=$G16,1,0),"") | P16: 1 | Q16: =IF($G16<>"",IF(P16=$G16,1,0),"") | R16: 1 | S16: =IF($G16<>"",IF(R16=$G16,1,0),"") | T16: 1 | U16: =IF($G16<>"",IF(T16=$G16,1,0),"") | V16: 1 | W16: =IF($G16<>"",IF(V16=$G16,1,0),"") | X16: 1 | Y16: =IF($G16<>"",IF(X16=$G16,1,0),"") | Z16: 1 | AA16: =IF($G16<>"",IF(Z16=$G16,1,0),"") | AB16: 1 | AC16: =IF($G16<>"",IF(AB16=$G16,1,0),"") | AD16: X | AE16: =IF($G16<>"",IF(AD16=$G16,1,0),"") | AF16: 1 | AG16: =IF($G16<>"",IF(AF16=$G16,1,0),"") | AH16: 1 | AI16: =IF($G16<>"",IF(AH16=$G16,1,0),"") | AJ16: X | AK16: =IF($G16<>"",IF(AJ16=$G16,1,0),"") | AL16: X | AM16: =IF($G16<>"",IF(AL16=$G16,1,0),"") | AN16: 1 | AO16: =IF($G16<>"",IF(AN16=$G16,1,0),"") | AP16: 1 | AQ16: =IF($G16<>"",IF(AP16=$G16,1,0),"")
A17: 15 | B17: Mar 16 giu | C17: 24:00 | D17: Girone H | E17: Arabia Saudita | F17: Uruguay | H17: 2 | I17: =IF($G17<>"",IF(H17=$G17,1,0),"") | J17: 2 | K17: =IF($G17<>"",IF(J17=$G17,1,0),"") | L17: X | M17: =IF($G17<>"",IF(L17=$G17,1,0),"") | N17: 2 | O17: =IF($G17<>"",IF(N17=$G17,1,0),"") | P17: 2 | Q17: =IF($G17<>"",IF(P17=$G17,1,0),"") | R17: 2 | S17: =IF($G17<>"",IF(R17=$G17,1,0),"") | T17: X | U17: =IF($G17<>"",IF(T17=$G17,1,0),"") | V17: 2 | W17: =IF($G17<>"",IF(V17=$G17,1,0),"") | X17: 2 | Y17: =IF($G17<>"",IF(X17=$G17,1,0),"") | Z17: 1 | AA17: =IF($G17<>"",IF(Z17=$G17,1,0),"") | AB17: 2 | AC17: =IF($G17<>"",IF(AB17=$G17,1,0),"") | AD17: X | AE17: =IF($G17<>"",IF(AD17=$G17,1,0),"") | AF17: 2 | AG17: =IF($G17<>"",IF(AF17=$G17,1,0),"") | AH17: 2 | AI17: =IF($G17<>"",IF(AH17=$G17,1,0),"") | AJ17: 2 | AK17: =IF($G17<>"",IF(AJ17=$G17,1,0),"") | AL17: X | AM17: =IF($G17<>"",IF(AL17=$G17,1,0),"") | AN17: 2 | AO17: =IF($G17<>"",IF(AN17=$G17,1,0),"") | AP17: 2 | AQ17: =IF($G17<>"",IF(AP17=$G17,1,0),"")
A18: 16 | B18: Mar 16 giu | C18: 03:00 | D18: Girone G | E18: Iran | F18: Nuova Zelanda | H18: 1 | I18: =IF($G18<>"",IF(H18=$G18,1,0),"") | J18: X | K18: =IF($G18<>"",IF(J18=$G18,1,0),"") | L18: X | M18: =IF($G18<>"",IF(L18=$G18,1,0),"") | N18: X | O18: =IF($G18<>"",IF(N18=$G18,1,0),"") | P18: X | Q18: =IF($G18<>"",IF(P18=$G18,1,0),"") | R18: X | S18: =IF($G18<>"",IF(R18=$G18,1,0),"") | T18: X | U18: =IF($G18<>"",IF(T18=$G18,1,0),"") | V18: 1 | W18: =IF($G18<>"",IF(V18=$G18,1,0),"") | X18: 1 | Y18: =IF($G18<>"",IF(X18=$G18,1,0),"") | Z18: 2 | AA18: =IF($G18<>"",IF(Z18=$G18,1,0),"") | AB18: X | AC18: =IF($G18<>"",IF(AB18=$G18,1,0),"") | AD18: 1 | AE18: =IF($G18<>"",IF(AD18=$G18,1,0),"") | AF18: x | AG18: =IF($G18<>"",IF(AF18=$G18,1,0),"") | AH18: 1 | AI18: =IF($G18<>"",IF(AH18=$G18,1,0),"") | AJ18: 1 | AK18: =IF($G18<>"",IF(AJ18=$G18,1,0),"") | AL18: 1 | AM18: =IF($G18<>"",IF(AL18=$G18,1,0),"") | AN18: 2 | AO18: =IF($G18<>"",IF(AN18=$G18,1,0),"") | AP18: 1 | AQ18: =IF($G18<>"",IF(AP18=$G18,1,0),"")
A19: 17 | B19: Mar 16 giu | C19: 21:00 | D19: Girone I | E19: Francia | F19: Senegal | H19: 1 | I19: =IF($G19<>"",IF(H19=$G19,1,0),"") | J19: 1 | K19: =IF($G19<>"",IF(J19=$G19,1,0),"") | L19: 1 | M19: =IF($G19<>"",IF(L19=$G19,1,0),"") | N19: X | O19: =IF($G19<>"",IF(N19=$G19,1,0),"") | P19: 1 | Q19: =IF($G19<>"",IF(P19=$G19,1,0),"") | R19: 1 | S19: =IF($G19<>"",IF(R19=$G19,1,0),"") | T19: 1 | U19: =IF($G19<>"",IF(T19=$G19,1,0),"") | V19: X | W19: =IF($G19<>"",IF(V19=$G19,1,0),"") | X19: 1 | Y19: =IF($G19<>"",IF(X19=$G19,1,0),"") | Z19: 1 | AA19: =IF($G19<>"",IF(Z19=$G19,1,0),"") | AB19: 1 | AC19: =IF($G19<>"",IF(AB19=$G19,1,0),"") | AD19: 1 | AE19: =IF($G19<>"",IF(AD19=$G19,1,0),"") | AF19: 1 | AG19: =IF($G19<>"",IF(AF19=$G19,1,0),"") | AH19: 1 | AI19: =IF($G19<>"",IF(AH19=$G19,1,0),"") | AJ19: 2 | AK19: =IF($G19<>"",IF(AJ19=$G19,1,0),"") | AL19: 1 | AM19: =IF($G19<>"",IF(AL19=$G19,1,0),"") | AN19: 1 | AO19: =IF($G19<>"",IF(AN19=$G19,1,0),"") | AP19: 1 | AQ19: =IF($G19<>"",IF(AP19=$G19,1,0),"")
A20: 18 | B20: Mer 17 giu | C20: 24:00 | D20: Girone I | E20: Iraq | F20: Norvegia | H20: 2 | I20: =IF($G20<>"",IF(H20=$G20,1,0),"") | J20: 2 | K20: =IF($G20<>"",IF(J20=$G20,1,0),"") | L20: 2 | M20: =IF($G20<>"",IF(L20=$G20,1,0),"") | N20: 2 | O20: =IF($G20<>"",IF(N20=$G20,1,0),"") | P20: 2 | Q20: =IF($G20<>"",IF(P20=$G20,1,0),"") | R20: 2 | S20: =IF($G20<>"",IF(R20=$G20,1,0),"") | T20: 2 | U20: =IF($G20<>"",IF(T20=$G20,1,0),"") | V20: 2 | W20: =IF($G20<>"",IF(V20=$G20,1,0),"") | X20: 2 | Y20: =IF($G20<>"",IF(X20=$G20,1,0),"") | Z20: 2 | AA20: =IF($G20<>"",IF(Z20=$G20,1,0),"") | AB20: 2 | AC20: =IF($G20<>"",IF(AB20=$G20,1,0),"") | AD20: X | AE20: =IF($G20<>"",IF(AD20=$G20,1,0),"") | AF20: 2 | AG20: =IF($G20<>"",IF(AF20=$G20,1,0),"") | AH20: 2 | AI20: =IF($G20<>"",IF(AH20=$G20,1,0),"") | AJ20: 2 | AK20: =IF($G20<>"",IF(AJ20=$G20,1,0),"") | AL20: 2 | AM20: =IF($G20<>"",IF(AL20=$G20,1,0),"") | AN20: 2 | AO20: =IF($G20<>"",IF(AN20=$G20,1,0),"") | AP20: 2 | AQ20: =IF($G20<>"",IF(AP20=$G20,1,0),"")
A21: 19 | B21: Mer 17 giu | C21: 03:00 | D21: Girone J | E21: Argentina | F21: Algeria | H21: 1 | I21: =IF($G21<>"",IF(H21=$G21,1,0),"") | J21: 1 | K21: =IF($G21<>"",IF(J21=$G21,1,0),"") | L21: 1 | M21: =IF($G21<>"",IF(L21=$G21,1,0),"") | N21: 1 | O21: =IF($G21<>"",IF(N21=$G21,1,0),"") | P21: 1 | Q21: =IF($G21<>"",IF(P21=$G21,1,0),"") | R21: 1 | S21: =IF($G21<>"",IF(R21=$G21,1,0),"") | T21: 1 | U21: =IF($G21<>"",IF(T21=$G21,1,0),"") | V21: X | W21: =IF($G21<>"",IF(V21=$G21,1,0),"") | X21: 1 | Y21: =IF($G21<>"",IF(X21=$G21,1,0),"") | Z21: 1 | AA21: =IF($G21<>"",IF(Z21=$G21,1,0),"") | AB21: 1 | AC21: =IF($G21<>"",IF(AB21=$G21,1,0),"") | AD21: 1 | AE21: =IF($G21<>"",IF(AD21=$G21,1,0),"") | AF21: 1 | AG21: =IF($G21<>"",IF(AF21=$G21,1,0),"") | AH21: 1 | AI21: =IF($G21<>"",IF(AH21=$G21,1,0),"") | AJ21: 1 | AK21: =IF($G21<>"",IF(AJ21=$G21,1,0),"") | AL21: 1 | AM21: =IF($G21<>"",IF(AL21=$G21,1,0),"") | AN21: 1 | AO21: =IF($G21<>"",IF(AN21=$G21,1,0),"") | AP21: 1 | AQ21: =IF($G21<>"",IF(AP21=$G21,1,0),"")
A22: 20 | B22: Mer 17 giu | C22: 06:00 | D22: Girone J | E22: Austria | F22: Giordania | H22: X | I22: =IF($G22<>"",IF(H22=$G22,1,0),"") | J22: 1 | K22: =IF($G22<>"",IF(J22=$G22,1,0),"") | L22: X | M22: =IF($G22<>"",IF(L22=$G22,1,0),"") | N22: 1 | O22: =IF($G22<>"",IF(N22=$G22,1,0),"") | P22: 1 | Q22: =IF($G22<>"",IF(P22=$G22,1,0),"") | R22: 1 | S22: =IF($G22<>"",IF(R22=$G22,1,0),"") | T22: 1 | U22: =IF($G22<>"",IF(T22=$G22,1,0),"") | V22: 1 | W22: =IF($G22<>"",IF(V22=$G22,1,0),"") | X22: 1 | Y22: =IF($G22<>"",IF(X22=$G22,1,0),"") | Z22: 1 | AA22: =IF($G22<>"",IF(Z22=$G22,1,0),"") | AB22: X | AC22: =IF($G22<>"",IF(AB22=$G22,1,0),"") | AD22: X | AE22: =IF($G22<>"",IF(AD22=$G22,1,0),"") | AF22: 1 | AG22: =IF($G22<>"",IF(AF22=$G22,1,0),"") | AH22: 1 | AI22: =IF($G22<>"",IF(AH22=$G22,1,0),"") | AJ22: 1 | AK22: =IF($G22<>"",IF(AJ22=$G22,1,0),"") | AL22: X | AM22: =IF($G22<>"",IF(AL22=$G22,1,0),"") | AN22: 1 | AO22: =IF($G22<>"",IF(AN22=$G22,1,0),"") | AP22: 1 | AQ22: =IF($G22<>"",IF(AP22=$G22,1,0),"")
A23: 21 | B23: Mer 17 giu | C23: 19:00 | D23: Girone K | E23: Portogallo | F23: R. D. del Congo | H23: 1 | I23: =IF($G23<>"",IF(H23=$G23,1,0),"") | J23: 1 | K23: =IF($G23<>"",IF(J23=$G23,1,0),"") | L23: 1 | M23: =IF($G23<>"",IF(L23=$G23,1,0),"") | N23: 1 | O23: =IF($G23<>"",IF(N23=$G23,1,0),"") | P23: 1 | Q23: =IF($G23<>"",IF(P23=$G23,1,0),"") | R23: 1 | S23: =IF($G23<>"",IF(R23=$G23,1,0),"") | T23: 1 | U23: =IF($G23<>"",IF(T23=$G23,1,0),"") | V23: 1 | W23: =IF($G23<>"",IF(V23=$G23,1,0),"") | X23: 1 | Y23: =IF($G23<>"",IF(X23=$G23,1,0),"") | Z23: 1 | AA23: =IF($G23<>"",IF(Z23=$G23,1,0),"") | AB23: 1 | AC23: =IF($G23<>"",IF(AB23=$G23,1,0),"") | AD23: 1 | AE23: =IF($G23<>"",IF(AD23=$G23,1,0),"") | AF23: 1 | AG23: =IF($G23<>"",IF(AF23=$G23,1,0),"") | AH23: 1 | AI23: =IF($G23<>"",IF(AH23=$G23,1,0),"") | AJ23: 1 | AK23: =IF($G23<>"",IF(AJ23=$G23,1,0),"") | AL23: 1 | AM23: =IF($G23<>"",IF(AL23=$G23,1,0),"") | AN23: 1 | AO23: =IF($G23<>"",IF(AN23=$G23,1,0),"") | AP23: 1 | AQ23: =IF($G23<>"",IF(AP23=$G23,1,0),"")
A24: 22 | B24: Mer 17 giu | C24: 22:00 | D24: Girone L | E24: Inghilterra | F24: Croazia | H24: 1 | I24: =IF($G24<>"",IF(H24=$G24,1,0),"") | J24: 1 | K24: =IF($G24<>"",IF(J24=$G24,1,0),"") | L24: 1 | M24: =IF($G24<>"",IF(L24=$G24,1,0),"") | N24: X | O24: =IF($G24<>"",IF(N24=$G24,1,0),"") | P24: X | Q24: =IF($G24<>"",IF(P24=$G24,1,0),"") | R24: 1 | S24: =IF($G24<>"",IF(R24=$G24,1,0),"") | T24: 1 | U24: =IF($G24<>"",IF(T24=$G24,1,0),"") | V24: X | W24: =IF($G24<>"",IF(V24=$G24,1,0),"") | X24: X | Y24: =IF($G24<>"",IF(X24=$G24,1,0),"") | Z24: 1 | AA24: =IF($G24<>"",IF(Z24=$G24,1,0),"") | AB24: X | AC24: =IF($G24<>"",IF(AB24=$G24,1,0),"") | AD24: 1 | AE24: =IF($G24<>"",IF(AD24=$G24,1,0),"") | AF24: x | AG24: =IF($G24<>"",IF(AF24=$G24,1,0),"") | AH24: 1 | AI24: =IF($G24<>"",IF(AH24=$G24,1,0),"") | AJ24: X | AK24: =IF($G24<>"",IF(AJ24=$G24,1,0),"") | AL24: 2 | AM24: =IF($G24<>"",IF(AL24=$G24,1,0),"") | AN24: X | AO24: =IF($G24<>"",IF(AN24=$G24,1,0),"") | AP24: 1 | AQ24: =IF($G24<>"",IF(AP24=$G24,1,0),"")
A25: 23 | B25: Gio 18 giu | C25: 01:00 | D25: Girone L | E25: Ghana | F25: Panama | H25: X | I25: =IF($G25<>"",IF(H25=$G25,1,0),"") | J25: 1 | K25: =IF($G25<>"",IF(J25=$G25,1,0),"") | L25: X | M25: =IF($G25<>"",IF(L25=$G25,1,0),"") | N25: 1 | O25: =IF($G25<>"",IF(N25=$G25,1,0),"") | P25: X | Q25: =IF($G25<>"",IF(P25=$G25,1,0),"") | R25: 1 | S25: =IF($G25<>"",IF(R25=$G25,1,0),"") | T25: 1 | U25: =IF($G25<>"",IF(T25=$G25,1,0),"") | V25: 1 | W25: =IF($G25<>"",IF(V25=$G25,1,0),"") | X25: 1 | Y25: =IF($G25<>"",IF(X25=$G25,1,0),"") | Z25: X | AA25: =IF($G25<>"",IF(Z25=$G25,1,0),"") | AB25: 1 | AC25: =IF($G25<>"",IF(AB25=$G25,1,0),"") | AD25: X | AE25: =IF($G25<>"",IF(AD25=$G25,1,0),"") | AF25: 2 | AG25: =IF($G25<>"",IF(AF25=$G25,1,0),"") | AH25: X | AI25: =IF($G25<>"",IF(AH25=$G25,1,0),"") | AJ25: 1 | AK25: =IF($G25<>"",IF(AJ25=$G25,1,0),"") | AL25: 1 | AM25: =IF($G25<>"",IF(AL25=$G25,1,0),"") | AN25: 1 | AO25: =IF($G25<>"",IF(AN25=$G25,1,0),"") | AP25: 2 | AQ25: =IF($G25<>"",IF(AP25=$G25,1,0),"")
A26: 24 | B26: Gio 18 giu | C26: 04:00 | D26: Girone K | E26: Uzbekistan | F26: Colombia | H26: 1 | I26: =IF($G26<>"",IF(H26=$G26,1,0),"") | J26: 2 | K26: =IF($G26<>"",IF(J26=$G26,1,0),"") | L26: 2 | M26: =IF($G26<>"",IF(L26=$G26,1,0),"") | N26: X | O26: =IF($G26<>"",IF(N26=$G26,1,0),"") | P26: 2 | Q26: =IF($G26<>"",IF(P26=$G26,1,0),"") | R26: 2 | S26: =IF($G26<>"",IF(R26=$G26,1,0),"") | T26: 2 | U26: =IF($G26<>"",IF(T26=$G26,1,0),"") | V26: 1 | W26: =IF($G26<>"",IF(V26=$G26,1,0),"") | X26: 2 | Y26: =IF($G26<>"",IF(X26=$G26,1,0),"") | Z26: 2 | AA26: =IF($G26<>"",IF(Z26=$G26,1,0),"") | AB26: 1 | AC26: =IF($G26<>"",IF(AB26=$G26,1,0),"") | AD26: 1 | AE26: =IF($G26<>"",IF(AD26=$G26,1,0),"") | AF26: 1 | AG26: =IF($G26<>"",IF(AF26=$G26,1,0),"") | AH26: 2 | AI26: =IF($G26<>"",IF(AH26=$G26,1,0),"") | AJ26: 2 | AK26: =IF($G26<>"",IF(AJ26=$G26,1,0),"") | AL26: 2 | AM26: =IF($G26<>"",IF(AL26=$G26,1,0),"") | AN26: 2 | AO26: =IF($G26<>"",IF(AN26=$G26,1,0),"") | AP26: 2 | AQ26: =IF($G26<>"",IF(AP26=$G26,1,0),"")
A27: 25 | B27: Gio 18 giu | C27: 18:00 | D27: Girone A | E27: Repubblica Ceca | F27: Sudafrica | H27: 1 | I27: =IF($G27<>"",IF(H27=$G27,1,0),"") | J27: 1 | K27: =IF($G27<>"",IF(J27=$G27,1,0),"") | L27: 2 | M27: =IF($G27<>"",IF(L27=$G27,1,0),"") | N27: 2 | O27: =IF($G27<>"",IF(N27=$G27,1,0),"") | P27: 1 | Q27: =IF($G27<>"",IF(P27=$G27,1,0),"") | R27: X | S27: =IF($G27<>"",IF(R27=$G27,1,0),"") | T27: X | U27: =IF($G27<>"",IF(T27=$G27,1,0),"") | V27: 1 | W27: =IF($G27<>"",IF(V27=$G27,1,0),"") | X27: 1 | Y27: =IF($G27<>"",IF(X27=$G27,1,0),"") | Z27: 2 | AA27: =IF($G27<>"",IF(Z27=$G27,1,0),"") | AB27: X | AC27: =IF($G27<>"",IF(AB27=$G27,1,0),"") | AD27: X | AE27: =IF($G27<>"",IF(AD27=$G27,1,0),"") | AF27: 2 | AG27: =IF($G27<>"",IF(AF27=$G27,1,0),"") | AH27: 1 | AI27: =IF($G27<>"",IF(AH27=$G27,1,0),"") | AJ27: 2 | AK27: =IF($G27<>"",IF(AJ27=$G27,1,0),"") | AL27: 1 | AM27: =IF($G27<>"",IF(AL27=$G27,1,0),"") | AN27: 1 | AO27: =IF($G27<>"",IF(AN27=$G27,1,0),"") | AP27: 1 | AQ27: =IF($G27<>"",IF(AP27=$G27,1,0),"")
A28: 26 | B28: Gio 18 giu | C28: 21:00 | D28: Girone B | E28: Svizzera | F28: Bosnia-Erzegovina | H28: 2 | I28: =IF($G28<>"",IF(H28=$G28,1,0),"") | J28: X | K28: =IF($G28<>"",IF(J28=$G28,1,0),"") | L28: 1 | M28: =IF($G28<>"",IF(L28=$G28,1,0),"") | N28: 1 | O28: =IF($G28<>"",IF(N28=$G28,1,0),"") | P28: 1 | Q28: =IF($G28<>"",IF(P28=$G28,1,0),"") | R28: X | S28: =IF($G28<>"",IF(R28=$G28,1,0),"") | T28: 1 | U28: =IF($G28<>"",IF(T28=$G28,1,0),"") | V28: X | W28: =IF($G28<>"",IF(V28=$G28,1,0),"") | X28: 1 | Y28: =IF($G28<>"",IF(X28=$G28,1,0),"") | Z28: 1 | AA28: =IF($G28<>"",IF(Z28=$G28,1,0),"") | AB28: 1 | AC28: =IF($G28<>"",IF(AB28=$G28,1,0),"") | AD28: X | AE28: =IF($G28<>"",IF(AD28=$G28,1,0),"") | AF28: 1 | AG28: =IF($G28<>"",IF(AF28=$G28,1,0),"") | AH28: 1 | AI28: =IF($G28<>"",IF(AH28=$G28,1,0),"") | AJ28: 1 | AK28: =IF($G28<>"",IF(AJ28=$G28,1,0),"") | AL28: 1 | AM28: =IF($G28<>"",IF(AL28=$G28,1,0),"") | AN28: 2 | AO28: =IF($G28<>"",IF(AN28=$G28,1,0),"") | AP28: 1 | AQ28: =IF($G28<>"",IF(AP28=$G28,1,0),"")
A29: 27 | B29: Ven 19 giu | C29: 24:00 | D29: Girone B | E29: Canada | F29: Qatar | H29: X | I29: =IF($G29<>"",IF(H29=$G29,1,0),"") | J29: 1 | K29: =IF($G29<>"",IF(J29=$G29,1,0),"") | L29: 1 | M29: =IF($G29<>"",IF(L29=$G29,1,0),"") | N29: 2 | O29: =IF($G29<>"",IF(N29=$G29,1,0),"") | P29: 1 | Q29: =IF($G29<>"",IF(P29=$G29,1,0),"") | R29: 1 | S29: =IF($G29<>"",IF(R29=$G29,1,0),"") | T29: 1 | U29: =IF($G29<>"",IF(T29=$G29,1,0),"") | V29: 1 | W29: =IF($G29<>"",IF(V29=$G29,1,0),"") | X29: 1 | Y29: =IF($G29<>"",IF(X29=$G29,1,0),"") | Z29: X | AA29: =IF($G29<>"",IF(Z29=$G29,1,0),"") | AB29: 1 | AC29: =IF($G29<>"",IF(AB29=$G29,1,0),"") | AD29: X | AE29: =IF($G29<>"",IF(AD29=$G29,1,0),"") | AF29: 1 | AG29: =IF($G29<>"",IF(AF29=$G29,1,0),"") | AH29: 1 | AI29: =IF($G29<>"",IF(AH29=$G29,1,0),"") | AJ29: 1 | AK29: =IF($G29<>"",IF(AJ29=$G29,1,0),"") | AL29: 1 | AM29: =IF($G29<>"",IF(AL29=$G29,1,0),"") | AN29: 1 | AO29: =IF($G29<>"",IF(AN29=$G29,1,0),"") | AP29: 1 | AQ29: =IF($G29<>"",IF(AP29=$G29,1,0),"")
A30: 28 | B30: Ven 19 giu | C30: 03:00 | D30: Girone A | E30: Messico | F30: Corea del Sud | H30: X | I30: =IF($G30<>"",IF(H30=$G30,1,0),"") | J30: X | K30: =IF($G30<>"",IF(J30=$G30,1,0),"") | L30: 1 | M30: =IF($G30<>"",IF(L30=$G30,1,0),"") | N30: 1 | O30: =IF($G30<>"",IF(N30=$G30,1,0),"") | P30: 1 | Q30: =IF($G30<>"",IF(P30=$G30,1,0),"") | R30: 2 | S30: =IF($G30<>"",IF(R30=$G30,1,0),"") | T30: 1 | U30: =IF($G30<>"",IF(T30=$G30,1,0),"") | V30: X | W30: =IF($G30<>"",IF(V30=$G30,1,0),"") | X30: 1 | Y30: =IF($G30<>"",IF(X30=$G30,1,0),"") | Z30: 1 | AA30: =IF($G30<>"",IF(Z30=$G30,1,0),"") | AB30: X | AC30: =IF($G30<>"",IF(AB30=$G30,1,0),"") | AD30: 1 | AE30: =IF($G30<>"",IF(AD30=$G30,1,0),"") | AF30: x | AG30: =IF($G30<>"",IF(AF30=$G30,1,0),"") | AH30: 1 | AI30: =IF($G30<>"",IF(AH30=$G30,1,0),"") | AJ30: 1 | AK30: =IF($G30<>"",IF(AJ30=$G30,1,0),"") | AL30: X | AM30: =IF($G30<>"",IF(AL30=$G30,1,0),"") | AN30: 1 | AO30: =IF($G30<>"",IF(AN30=$G30,1,0),"") | AP30: 1 | AQ30: =IF($G30<>"",IF(AP30=$G30,1,0),"")
A31: 29 | B31: Ven 19 giu | C31: 21:00 | D31: Girone D | E31: Stati Uniti | F31: Australia | H31: 1 | I31: =IF($G31<>"",IF(H31=$G31,1,0),"") | J31: X | K31: =IF($G31<>"",IF(J31=$G31,1,0),"") | L31: 1 | M31: =IF($G31<>"",IF(L31=$G31,1,0),"") | N31: X | O31: =IF($G31<>"",IF(N31=$G31,1,0),"") | P31: 1 | Q31: =IF($G31<>"",IF(P31=$G31,1,0),"") | R31: 1 | S31: =IF($G31<>"",IF(R31=$G31,1,0),"") | T31: 1 | U31: =IF($G31<>"",IF(T31=$G31,1,0),"") | V31: 1 | W31: =IF($G31<>"",IF(V31=$G31,1,0),"") | X31: 1 | Y31: =IF($G31<>"",IF(X31=$G31,1,0),"") | Z31: X | AA31: =IF($G31<>"",IF(Z31=$G31,1,0),"") | AB31: 2 | AC31: =IF($G31<>"",IF(AB31=$G31,1,0),"") | AD31: 1 | AE31: =IF($G31<>"",IF(AD31=$G31,1,0),"") | AF31: 2 | AG31: =IF($G31<>"",IF(AF31=$G31,1,0),"") | AH31: 1 | AI31: =IF($G31<>"",IF(AH31=$G31,1,0),"") | AJ31: 1 | AK31: =IF($G31<>"",IF(AJ31=$G31,1,0),"") | AL31: 1 | AM31: =IF($G31<>"",IF(AL31=$G31,1,0),"") | AN31: 1 | AO31: =IF($G31<>"",IF(AN31=$G31,1,0),"") | AP31: 1 | AQ31: =IF($G31<>"",IF(AP31=$G31,1,0),"")
A32: 30 | B32: Sab 20 giu | C32: 24:00 | D32: Girone C | E32: Scozia | F32: Marocco | H32: 2 | I32: =IF($G32<>"",IF(H32=$G32,1,0),"") | J32: 2 | K32: =IF($G32<>"",IF(J32=$G32,1,0),"") | L32: 1 | M32: =IF($G32<>"",IF(L32=$G32,1,0),"") | N32: 2 | O32: =IF($G32<>"",IF(N32=$G32,1,0),"") | P32: 2 | Q32: =IF($G32<>"",IF(P32=$G32,1,0),"") | R32: X | S32: =IF($G32<>"",IF(R32=$G32,1,0),"") | T32: 2 | U32: =IF($G32<>"",IF(T32=$G32,1,0),"") | V32: 2 | W32: =IF($G32<>"",IF(V32=$G32,1,0),"") | X32: 1 | Y32: =IF($G32<>"",IF(X32=$G32,1,0),"") | Z32: X | AA32: =IF($G32<>"",IF(Z32=$G32,1,0),"") | AB32: 2 | AC32: =IF($G32<>"",IF(AB32=$G32,1,0),"") | AD32: 2 | AE32: =IF($G32<>"",IF(AD32=$G32,1,0),"") | AF32: 2 | AG32: =IF($G32<>"",IF(AF32=$G32,1,0),"") | AH32: 2 | AI32: =IF($G32<>"",IF(AH32=$G32,1,0),"") | AJ32: 2 | AK32: =IF($G32<>"",IF(AJ32=$G32,1,0),"") | AL32: 2 | AM32: =IF($G32<>"",IF(AL32=$G32,1,0),"") | AN32: 2 | AO32: =IF($G32<>"",IF(AN32=$G32,1,0),"") | AP32: 2 | AQ32: =IF($G32<>"",IF(AP32=$G32,1,0),"")
A33: 31 | B33: Sab 20 giu | C33: 02:30 | D33: Girone C | E33: Brasile | F33: Haiti | H33: 1 | I33: =IF($G33<>"",IF(H33=$G33,1,0),"") | J33: 1 | K33: =IF($G33<>"",IF(J33=$G33,1,0),"") | L33: 1 | M33: =IF($G33<>"",IF(L33=$G33,1,0),"") | N33: 1 | O33: =IF($G33<>"",IF(N33=$G33,1,0),"") | P33: 1 | Q33: =IF($G33<>"",IF(P33=$G33,1,0),"") | R33: 1 | S33: =IF($G33<>"",IF(R33=$G33,1,0),"") | T33: 1 | U33: =IF($G33<>"",IF(T33=$G33,1,0),"") | V33: 1 | W33: =IF($G33<>"",IF(V33=$G33,1,0),"") | X33: 1 | Y33: =IF($G33<>"",IF(X33=$G33,1,0),"") | Z33: 1 | AA33: =IF($G33<>"",IF(Z33=$G33,1,0),"") | AB33: 1 | AC33: =IF($G33<>"",IF(AB33=$G33,1,0),"") | AD33: 1 | AE33: =IF($G33<>"",IF(AD33=$G33,1,0),"") | AF33: 1 | AG33: =IF($G33<>"",IF(AF33=$G33,1,0),"") | AH33: 1 | AI33: =IF($G33<>"",IF(AH33=$G33,1,0),"") | AJ33: 1 | AK33: =IF($G33<>"",IF(AJ33=$G33,1,0),"") | AL33: 1 | AM33: =IF($G33<>"",IF(AL33=$G33,1,0),"") | AN33: 1 | AO33: =IF($G33<>"",IF(AN33=$G33,1,0),"") | AP33: 1 | AQ33: =IF($G33<>"",IF(AP33=$G33,1,0),"")
A34: 32 | B34: Sab 20 giu | C34: 05:00 | D34: Girone D | E34: Turchia | F34: Paraguay | H34: 1 | I34: =IF($G34<>"",IF(H34=$G34,1,0),"") | J34: 1 | K34: =IF($G34<>"",IF(J34=$G34,1,0),"") | L34: 2 | M34: =IF($G34<>"",IF(L34=$G34,1,0),"") | N34: 1 | O34: =IF($G34<>"",IF(N34=$G34,1,0),"") | P34: X | Q34: =IF($G34<>"",IF(P34=$G34,1,0),"") | R34: 1 | S34: =IF($G34<>"",IF(R34=$G34,1,0),"") | T34: 1 | U34: =IF($G34<>"",IF(T34=$G34,1,0),"") | V34: 1 | W34: =IF($G34<>"",IF(V34=$G34,1,0),"") | X34: 1 | Y34: =IF($G34<>"",IF(X34=$G34,1,0),"") | Z34: X | AA34: =IF($G34<>"",IF(Z34=$G34,1,0),"") | AB34: 1 | AC34: =IF($G34<>"",IF(AB34=$G34,1,0),"") | AD34: 2 | AE34: =IF($G34<>"",IF(AD34=$G34,1,0),"") | AF34: 1 | AG34: =IF($G34<>"",IF(AF34=$G34,1,0),"") | AH34: X | AI34: =IF($G34<>"",IF(AH34=$G34,1,0),"") | AJ34: X | AK34: =IF($G34<>"",IF(AJ34=$G34,1,0),"") | AL34: 1 | AM34: =IF($G34<>"",IF(AL34=$G34,1,0),"") | AN34: 1 | AO34: =IF($G34<>"",IF(AN34=$G34,1,0),"") | AP34: 1 | AQ34: =IF($G34<>"",IF(AP34=$G34,1,0),"")
A35: 33 | B35: Sab 20 giu | C35: 19:00 | D35: Girone F | E35: Paesi Bassi | F35: Svezia | H35: 1 | I35: =IF($G35<>"",IF(H35=$G35,1,0),"") | J35: 1 | K35: =IF($G35<>"",IF(J35=$G35,1,0),"") | L35: X | M35: =IF($G35<>"",IF(L35=$G35,1,0),"") | N35: 2 | O35: =IF($G35<>"",IF(N35=$G35,1,0),"") | P35: 1 | Q35: =IF($G35<>"",IF(P35=$G35,1,0),"") | R35: 1 | S35: =IF($G35<>"",IF(R35=$G35,1,0),"") | T35: X | U35: =IF($G35<>"",IF(T35=$G35,1,0),"") | V35: X | W35: =IF($G35<>"",IF(V35=$G35,1,0),"") | X35: 1 | Y35: =IF($G35<>"",IF(X35=$G35,1,0),"") | Z35: X | AA35: =IF($G35<>"",IF(Z35=$G35,1,0),"") | AB35: 1 | AC35: =IF($G35<>"",IF(AB35=$G35,1,0),"") | AD35: 1 | AE35: =IF($G35<>"",IF(AD35=$G35,1,0),"") | AF35: 1 | AG35: =IF($G35<>"",IF(AF35=$G35,1,0),"") | AH35: 1 | AI35: =IF($G35<>"",IF(AH35=$G35,1,0),"") | AJ35: X | AK35: =IF($G35<>"",IF(AJ35=$G35,1,0),"") | AL35: X | AM35: =IF($G35<>"",IF(AL35=$G35,1,0),"") | AN35: 1 | AO35: =IF($G35<>"",IF(AN35=$G35,1,0),"") | AP35: 1 | AQ35: =IF($G35<>"",IF(AP35=$G35,1,0),"")
A36: 34 | B36: Sab 20 giu | C36: 22:00 | D36: Girone E | E36: Germania | F36: Costa d'Avorio | H36: 1 | I36: =IF($G36<>"",IF(H36=$G36,1,0),"") | J36: 1 | K36: =IF($G36<>"",IF(J36=$G36,1,0),"") | L36: 1 | M36: =IF($G36<>"",IF(L36=$G36,1,0),"") | N36: 1 | O36: =IF($G36<>"",IF(N36=$G36,1,0),"") | P36: 1 | Q36: =IF($G36<>"",IF(P36=$G36,1,0),"") | R36: 1 | S36: =IF($G36<>"",IF(R36=$G36,1,0),"") | T36: 1 | U36: =IF($G36<>"",IF(T36=$G36,1,0),"") | V36: 1 | W36: =IF($G36<>"",IF(V36=$G36,1,0),"") | X36: 1 | Y36: =IF($G36<>"",IF(X36=$G36,1,0),"") | Z36: 1 | AA36: =IF($G36<>"",IF(Z36=$G36,1,0),"") | AB36: 1 | AC36: =IF($G36<>"",IF(AB36=$G36,1,0),"") | AD36: 1 | AE36: =IF($G36<>"",IF(AD36=$G36,1,0),"") | AF36: 1 | AG36: =IF($G36<>"",IF(AF36=$G36,1,0),"") | AH36: 1 | AI36: =IF($G36<>"",IF(AH36=$G36,1,0),"") | AJ36: X | AK36: =IF($G36<>"",IF(AJ36=$G36,1,0),"") | AL36: 1 | AM36: =IF($G36<>"",IF(AL36=$G36,1,0),"") | AN36: 2 | AO36: =IF($G36<>"",IF(AN36=$G36,1,0),"") | AP36: 1 | AQ36: =IF($G36<>"",IF(AP36=$G36,1,0),"")
A37: 35 | B37: Dom 21 giu | C37: 02:00 | D37: Girone E | E37: Ecuador | F37: Curaçao | H37: X | I37: =IF($G37<>"",IF(H37=$G37,1,0),"") | J37: 1 | K37: =IF($G37<>"",IF(J37=$G37,1,0),"") | L37: X | M37: =IF($G37<>"",IF(L37=$G37,1,0),"") | N37: 1 | O37: =IF($G37<>"",IF(N37=$G37,1,0),"") | P37: 1 | Q37: =IF($G37<>"",IF(P37=$G37,1,0),"") | R37: 1 | S37: =IF($G37<>"",IF(R37=$G37,1,0),"") | T37: 1 | U37: =IF($G37<>"",IF(T37=$G37,1,0),"") | V37: 1 | W37: =IF($G37<>"",IF(V37=$G37,1,0),"") | X37: 1 | Y37: =IF($G37<>"",IF(X37=$G37,1,0),"") | Z37: X | AA37: =IF($G37<>"",IF(Z37=$G37,1,0),"") | AB37: 2 | AC37: =IF($G37<>"",IF(AB37=$G37,1,0),"") | AD37: X | AE37: =IF($G37<>"",IF(AD37=$G37,1,0),"") | AF37: x | AG37: =IF($G37<>"",IF(AF37=$G37,1,0),"") | AH37: 1 | AI37: =IF($G37<>"",IF(AH37=$G37,1,0),"") | AJ37: 1 | AK37: =IF($G37<>"",IF(AJ37=$G37,1,0),"") | AL37: X | AM37: =IF($G37<>"",IF(AL37=$G37,1,0),"") | AN37: 1 | AO37: =IF($G37<>"",IF(AN37=$G37,1,0),"") | AP37: 1 | AQ37: =IF($G37<>"",IF(AP37=$G37,1,0),"")
A38: 36 | B38: Dom 21 giu | C38: 06:00 | D38: Girone F | E38: Tunisia | F38: Giappone | H38: 2 | I38: =IF($G38<>"",IF(H38=$G38,1,0),"") | J38: 2 | K38: =IF($G38<>"",IF(J38=$G38,1,0),"") | L38: 2 | M38: =IF($G38<>"",IF(L38=$G38,1,0),"") | N38: X | O38: =IF($G38<>"",IF(N38=$G38,1,0),"") | P38: 2 | Q38: =IF($G38<>"",IF(P38=$G38,1,0),"") | R38: 2 | S38: =IF($G38<>"",IF(R38=$G38,1,0),"") | T38: 2 | U38: =IF($G38<>"",IF(T38=$G38,1,0),"") | V38: X | W38: =IF($G38<>"",IF(V38=$G38,1,0),"") | X38: 2 | Y38: =IF($G38<>"",IF(X38=$G38,1,0),"") | Z38: 2 | AA38: =IF($G38<>"",IF(Z38=$G38,1,0),"") | AB38: 2 | AC38: =IF($G38<>"",IF(AB38=$G38,1,0),"") | AD38: X | AE38: =IF($G38<>"",IF(AD38=$G38,1,0),"") | AF38: 2 | AG38: =IF($G38<>"",IF(AF38=$G38,1,0),"") | AH38: 2 | AI38: =IF($G38<>"",IF(AH38=$G38,1,0),"") | AJ38: 2 | AK38: =IF($G38<>"",IF(AJ38=$G38,1,0),"") | AL38: 2 | AM38: =IF($G38<>"",IF(AL38=$G38,1,0),"") | AN38: X | AO38: =IF($G38<>"",IF(AN38=$G38,1,0),"") | AP38: 2 | AQ38: =IF($G38<>"",IF(AP38=$G38,1,0),"")
A39: 37 | B39: Dom 21 giu | C39: 18:00 | D39: Girone H | E39: Spagna | F39: Arabia Saudita | H39: 1 | I39: =IF($G39<>"",IF(H39=$G39,1,0),"") | J39: 1 | K39: =IF($G39<>"",IF(J39=$G39,1,0),"") | L39: 1 | M39: =IF($G39<>"",IF(L39=$G39,1,0),"") | N39: 1 | O39: =IF($G39<>"",IF(N39=$G39,1,0),"") | P39: 1 | Q39: =IF($G39<>"",IF(P39=$G39,1,0),"") | R39: 1 | S39: =IF($G39<>"",IF(R39=$G39,1,0),"") | T39: 1 | U39: =IF($G39<>"",IF(T39=$G39,1,0),"") | V39: 1 | W39: =IF($G39<>"",IF(V39=$G39,1,0),"") | X39: 1 | Y39: =IF($G39<>"",IF(X39=$G39,1,0),"") | Z39: 1 | AA39: =IF($G39<>"",IF(Z39=$G39,1,0),"") | AB39: 1 | AC39: =IF($G39<>"",IF(AB39=$G39,1,0),"") | AD39: 1 | AE39: =IF($G39<>"",IF(AD39=$G39,1,0),"") | AF39: 1 | AG39: =IF($G39<>"",IF(AF39=$G39,1,0),"") | AH39: 1 | AI39: =IF($G39<>"",IF(AH39=$G39,1,0),"") | AJ39: 1 | AK39: =IF($G39<>"",IF(AJ39=$G39,1,0),"") | AL39: 1 | AM39: =IF($G39<>"",IF(AL39=$G39,1,0),"") | AN39: 1 | AO39: =IF($G39<>"",IF(AN39=$G39,1,0),"") | AP39: 1 | AQ39: =IF($G39<>"",IF(AP39=$G39,1,0),"")
A40: 38 | B40: Dom 21 giu | C40: 21:00 | D40: Girone G | E40: Belgio | F40: Iran | H40: 1 | I40: =IF($G40<>"",IF(H40=$G40,1,0),"") | J40: 1 | K40: =IF($G40<>"",IF(J40=$G40,1,0),"") | L40: 1 | M40: =IF($G40<>"",IF(L40=$G40,1,0),"") | N40: 1 | O40: =IF($G40<>"",IF(N40=$G40,1,0),"") | P40: 1 | Q40: =IF($G40<>"",IF(P40=$G40,1,0),"") | R40: 1 | S40: =IF($G40<>"",IF(R40=$G40,1,0),"") | T40: 1 | U40: =IF($G40<>"",IF(T40=$G40,1,0),"") | V40: 1 | W40: =IF($G40<>"",IF(V40=$G40,1,0),"") | X40: 1 | Y40: =IF($G40<>"",IF(X40=$G40,1,0),"") | Z40: 1 | AA40: =IF($G40<>"",IF(Z40=$G40,1,0),"") | AB40: 1 | AC40: =IF($G40<>"",IF(AB40=$G40,1,0),"") | AD40: X | AE40: =IF($G40<>"",IF(AD40=$G40,1,0),"") | AF40: 1 | AG40: =IF($G40<>"",IF(AF40=$G40,1,0),"") | AH40: 1 | AI40: =IF($G40<>"",IF(AH40=$G40,1,0),"") | AJ40: 1 | AK40: =IF($G40<>"",IF(AJ40=$G40,1,0),"") | AL40: 1 | AM40: =IF($G40<>"",IF(AL40=$G40,1,0),"") | AN40: 1 | AO40: =IF($G40<>"",IF(AN40=$G40,1,0),"") | AP40: 1 | AQ40: =IF($G40<>"",IF(AP40=$G40,1,0),"")
...

Sheet Regolamento
A1: Benvenuti nel Mondialito di IZI S.p.A.! Questa prima parte del gioco consiste nell'indovinare gli esiti delle partite valevoli per i gironi del mondiale. Per ogni esito indovinato si ottiene un punto. Alla fine dei gironi, il giocatore che avrà totalizzato più punti sarà decretato vincitore della fase a gironi. Per partecipare, non dovete far altro che compilare le vostre previsioni nella rispettiva colonna verde. LA QUOTA DI ISCRIZIONE È PARI A 5 €, il vincitore prende tutto. A seguire, una volta definito il tabellone, insieme capiremo come e se costruire la seconda tappa del gioco.

Sheet Classifica

Sheet Elenco
A1: 1
A2: X
A3: 2
B4: Giocatore | C4: Punti
B5: ='Previsioni partecipanti'!H1 -> Leo Proietti | C5: ='Previsioni partecipanti'!I1 -> 0
B6: ='Previsioni partecipanti'!J1 -> Jack | C6: ='Previsioni partecipanti'!K1 -> 0
B7: {='Previsioni partecipanti'!L1:M1} -> Antonella | C7: 0
B8: {='Previsioni partecipanti'!N1:O1} -> Vito | C8: 0
B9: {='Previsioni partecipanti'!P1:Q1} -> Samuele | C9: 0
B10: {='Previsioni partecipanti'!R1:S1} -> Valerio | C10: 0
B11: {='Previsioni partecipanti'!T1:U1} -> Edoardo | C11: 0
B12: {='Previsioni partecipanti'!V1:W1} -> Tania | C12: 0
B13: {='Previsioni partecipanti'!X1:Y1} -> Pier | C13: 0
B14: {='Previsioni partecipanti'!Z1:AA1} -> Alessandra C. | C14: 0
B15: {='Previsioni partecipanti'!AB1:AC1} -> Alessandra P. | C15: 0
B16: {='Previsioni partecipanti'!AD1:AE1} -> Claudia A. | C16: 0
B17: {='Previsioni partecipanti'!AF1:AG1} -> Marco G. | C17: 0
B18: {='Previsioni partecipanti'!AH1:AI1} -> Alessio S. | C18: 0
B19: {='Previsioni partecipanti'!AJ1:AK1} -> Alessio R. | C19: 0
B20: {='Previsioni partecipanti'!AL1:AM1} -> Marco P. | C20: 0
B21: {='Previsioni partecipanti'!AN1:AO1} -> Khawla | C21: 0
B22: ='Previsioni partecipanti'!AP1 -> Federico R. | C22: ='Previsioni partecipanti'!AQ1 -> 0
